Workbook

Sheet case_predictions_full500
A1: case_id | B1: gold_label | C1: lott_routed_branch | D1: pred_lott_framework | E1: pred_rq_all500 | F1: pred_g20_standard | G1: pred_g20_cot | H1: pred_g20_ls | I1: pred_g25flash_standard | J1: pred_g25flash_cot | K1: pred_g25flash_ls | L1: pred_g25pro_standard | M1: pred_g25pro_cot | N1: pred_g25pro_ls | O1: correct_lott_framework | P1: hitpos_lott_framework | Q1: hitneg_lott_framework | R1: predpos_lott_framework | S1: correct_rq_all500 | T1: hitpos_rq_all500 | U1: hitneg_rq_all500 | V1: predpos_rq_all500 | W1: correct_g20_standard | X1: hitpos_g20_standard | Y1: hitneg_g20_standard | Z1: predpos_g20_standard | AA1: correct_g20_cot | AB1: hitpos_g20_cot | AC1: hitneg_g20_cot | AD1: predpos_g20_cot | AE1: correct_g20_ls | AF1: hitpos_g20_ls | AG1: hitneg_g20_ls | AH1: predpos_g20_ls | AI1: correct_g25flash_standard | AJ1: hitpos_g25flash_standard | AK1: hitneg_g25flash_standard | AL1: predpos_g25flash_standard | AM1: correct_g25flash_cot | AN1: hitpos_g25flash_cot | AO1: hitneg_g25flash_cot | AP1: predpos_g25flash_cot | AQ1: correct_g25flash_ls | AR1: hitpos_g25flash_ls | AS1: hitneg_g25flash_ls | AT1: predpos_g25flash_ls | AU1: correct_g25pro_standard | AV1: hitpos_g25pro_standard | AW1: hitneg_g25pro_standard | AX1: predpos_g25pro_standard | AY1: correct_g25pro_cot | AZ1: hitpos_g25pro_cot | BA1: hitneg_g25pro_cot | BB1: predpos_g25pro_cot | BC1: correct_g25pro_ls | BD1: hitpos_g25pro_ls | BE1: hitneg_g25pro_ls | BF1: predpos_g25pro_ls
A2: 201611317 | B2: 0 | C2: Direct | D2: 1 | E2: 0 | F2: 0 | G2: 0 | H2: 0 | I2: 0 | J2: 0 | K2: 0 | L2: 1 | M2: 0 | N2: 1 | O2: =IF(OR($B2="",D2=""),"",--(D2=$B2)) | P2: =IF(OR($B2="",D2=""),"",IF($B2=1,--(D2=1),"")) | Q2: =IF(OR($B2="",D2=""),"",IF($B2=0,--(D2=0),"")) | R2: =IF(D2="","",--(D2=1)) | S2: =IF(OR($B2="",E2=""),"",--(E2=$B2)) | T2: =IF(OR($B2="",E2=""),"",IF($B2=1,--(E2=1),"")) | U2: =IF(OR($B2="",E2=""),"",IF($B2=0,--(E2=0),"")) | V2: =IF(E2="","",--(E2=1)) | W2: =IF(OR($B2="",F2=""),"",--(F2=$B2)) | X2: =IF(OR($B2="",F2=""),"",IF($B2=1,--(F2=1),"")) | Y2: =IF(OR($B2="",F2=""),"",IF($B2=0,--(F2=0),"")) | Z2: =IF(F2="","",--(F2=1)) | AA2: =IF(OR($B2="",G2=""),"",--(G2=$B2)) | AB2: =IF(OR($B2="",G2=""),"",IF($B2=1,--(G2=1),"")) | AC2: =IF(OR($B2="",G2=""),"",IF($B2=0,--(G2=0),"")) | AD2: =IF(G2="","",--(G2=1)) | AE2: =IF(OR($B2="",H2=""),"",--(H2=$B2)) | AF2: =IF(OR($B2="",H2=""),"",IF($B2=1,--(H2=1),"")) | AG2: =IF(OR($B2="",H2=""),"",IF($B2=0,--(H2=0),"")) | AH2: =IF(H2="","",--(H2=1)) | AI2: =IF(OR($B2="",I2=""),"",--(I2=$B2)) | AJ2: =IF(OR($B2="",I2=""),"",IF($B2=1,--(I2=1),"")) | AK2: =IF(OR($B2="",I2=""),"",IF($B2=0,--(I2=0),"")) | AL2: =IF(I2="","",--(I2=1)) | AM2: =IF(OR($B2="",J2=""),"",--(J2=$B2)) | AN2: =IF(OR($B2="",J2=""),"",IF($B2=1,--(J2=1),"")) | AO2: =IF(OR($B2="",J2=""),"",IF($B2=0,--(J2=0),"")) | AP2: =IF(J2="","",--(J2=1)) | AQ2: =IF(OR($B2="",K2=""),"",--(K2=$B2)) | AR2: =IF(OR($B2="",K2=""),"",IF($B2=1,--(K2=1),"")) | AS2: =IF(OR($B2="",K2=""),"",IF($B2=0,--(K2=0),"")) | AT2: =IF(K2="","",--(K2=1)) | AU2: =IF(OR($B2="",L2=""),"",--(L2=$B2)) | AV2: =IF(OR($B2="",L2=""),"",IF($B2=1,--(L2=1),"")) | AW2: =IF(OR($B2="",L2=""),"",IF($B2=0,--(L2=0),"")) | AX2: =IF(L2="","",--(L2=1)) | AY2: =IF(OR($B2="",M2=""),"",--(M2=$B2)) | AZ2: =IF(OR($B2="",M2=""),"",IF($B2=1,--(M2=1),"")) | BA2: =IF(OR($B2="",M2=""),"",IF($B2=0,--(M2=0),"")) | BB2: =IF(M2="","",--(M2=1)) | BC2: =IF(OR($B2="",N2=""),"",--(N2=$B2)) | BD2: =IF(OR($B2="",N2=""),"",IF($B2=1,--(N2=1),"")) | BE2: =IF(OR($B2="",N2=""),"",IF($B2=0,--(N2=0),"")) | BF2: =IF(N2="","",--(N2=1))
A3: 201611319 | B3: 0 | C3: Direct | D3: 1 | E3: 0 | F3: 0 | G3: 0 | H3: 0 | I3: 0 | J3: 1 | K3: 0 | L3: 0 | M3: 1 | N3: 1 | O3: =IF(OR($B3="",D3=""),"",--(D3=$B3)) | P3: =IF(OR($B3="",D3=""),"",IF($B3=1,--(D3=1),"")) | Q3: =IF(OR($B3="",D3=""),"",IF($B3=0,--(D3=0),"")) | R3: =IF(D3="","",--(D3=1)) | S3: =IF(OR($B3="",E3=""),"",--(E3=$B3)) | T3: =IF(OR($B3="",E3=""),"",IF($B3=1,--(E3=1),"")) | U3: =IF(OR($B3="",E3=""),"",IF($B3=0,--(E3=0),"")) | V3: =IF(E3="","",--(E3=1)) | W3: =IF(OR($B3="",F3=""),"",--(F3=$B3)) | X3: =IF(OR($B3="",F3=""),"",IF($B3=1,--(F3=1),"")) | Y3: =IF(OR($B3="",F3=""),"",IF($B3=0,--(F3=0),"")) | Z3: =IF(F3="","",--(F3=1)) | AA3: =IF(OR($B3="",G3=""),"",--(G3=$B3)) | AB3: =IF(OR($B3="",G3=""),"",IF($B3=1,--(G3=1),"")) | AC3: =IF(OR($B3="",G3=""),"",IF($B3=0,--(G3=0),"")) | AD3: =IF(G3="","",--(G3=1)) | AE3: =IF(OR($B3="",H3=""),"",--(H3=$B3)) | AF3: =IF(OR($B3="",H3=""),"",IF($B3=1,--(H3=1),"")) | AG3: =IF(OR($B3="",H3=""),"",IF($B3=0,--(H3=0),"")) | AH3: =IF(H3="","",--(H3=1)) | AI3: =IF(OR($B3="",I3=""),"",--(I3=$B3)) | AJ3: =IF(OR($B3="",I3=""),"",IF($B3=1,--(I3=1),"")) | AK3: =IF(OR($B3="",I3=""),"",IF($B3=0,--(I3=0),"")) | AL3: =IF(I3="","",--(I3=1)) | AM3: =IF(OR($B3="",J3=""),"",--(J3=$B3)) | AN3: =IF(OR($B3="",J3=""),"",IF($B3=1,--(J3=1),"")) | AO3: =IF(OR($B3="",J3=""),"",IF($B3=0,--(J3=0),"")) | AP3: =IF(J3="","",--(J3=1)) | AQ3: =IF(OR($B3="",K3=""),"",--(K3=$B3)) | AR3: =IF(OR($B3="",K3=""),"",IF($B3=1,--(K3=1),"")) | AS3: =IF(OR($B3="",K3=""),"",IF($B3=0,--(K3=0),"")) | AT3: =IF(K3="","",--(K3=1)) | AU3: =IF(OR($B3="",L3=""),"",--(L3=$B3)) | AV3: =IF(OR($B3="",L3=""),"",IF($B3=1,--(L3=1),"")) | AW3: =IF(OR($B3="",L3=""),"",IF($B3=0,--(L3=0),"")) | AX3: =IF(L3="","",--(L3=1)) | AY3: =IF(OR($B3="",M3=""),"",--(M3=$B3)) | AZ3: =IF(OR($B3="",M3=""),"",IF($B3=1,--(M3=1),"")) | BA3: =IF(OR($B3="",M3=""),"",IF($B3=0,--(M3=0),"")) | BB3: =IF(M3="","",--(M3=1)) | BC3: =IF(OR($B3="",N3=""),"",--(N3=$B3)) | BD3: =IF(OR($B3="",N3=""),"",IF($B3=1,--(N3=1),"")) | BE3: =IF(OR($B3="",N3=""),"",IF($B3=0,--(N3=0),"")) | BF3: =IF(N3="","",--(N3=1))
A4: 201720729 | B4: 0 | C4: Direct | D4: 1 | E4: 0 | F4: 0 | G4: 0 | H4: 0 | I4: 0 | J4: 0 | K4: 0 | L4: 1 | M4: 1 | N4: 1 | O4: =IF(OR($B4="",D4=""),"",--(D4=$B4)) | P4: =IF(OR($B4="",D4=""),"",IF($B4=1,--(D4=1),"")) | Q4: =IF(OR($B4="",D4=""),"",IF($B4=0,--(D4=0),"")) | R4: =IF(D4="","",--(D4=1)) | S4: =IF(OR($B4="",E4=""),"",--(E4=$B4)) | T4: =IF(OR($B4="",E4=""),"",IF($B4=1,--(E4=1),"")) | U4: =IF(OR($B4="",E4=""),"",IF($B4=0,--(E4=0),"")) | V4: =IF(E4="","",--(E4=1)) | W4: =IF(OR($B4="",F4=""),"",--(F4=$B4)) | X4: =IF(OR($B4="",F4=""),"",IF($B4=1,--(F4=1),"")) | Y4: =IF(OR($B4="",F4=""),"",IF($B4=0,--(F4=0),"")) | Z4: =IF(F4="","",--(F4=1)) | AA4: =IF(OR($B4="",G4=""),"",--(G4=$B4)) | AB4: =IF(OR($B4="",G4=""),"",IF($B4=1,--(G4=1),"")) | AC4: =IF(OR($B4="",G4=""),"",IF($B4=0,--(G4=0),"")) | AD4: =IF(G4="","",--(G4=1)) | AE4: =IF(OR($B4="",H4=""),"",--(H4=$B4)) | AF4: =IF(OR($B4="",H4=""),"",IF($B4=1,--(H4=1),"")) | AG4: =IF(OR($B4="",H4=""),"",IF($B4=0,--(H4=0),"")) | AH4: =IF(H4="","",--(H4=1)) | AI4: =IF(OR($B4="",I4=""),"",--(I4=$B4)) | AJ4: =IF(OR($B4="",I4=""),"",IF($B4=1,--(I4=1),"")) | AK4: =IF(OR($B4="",I4=""),"",IF($B4=0,--(I4=0),"")) | AL4: =IF(I4="","",--(I4=1)) | AM4: =IF(OR($B4="",J4=""),"",--(J4=$B4)) | AN4: =IF(OR($B4="",J4=""),"",IF($B4=1,--(J4=1),"")) | AO4: =IF(OR($B4="",J4=""),"",IF($B4=0,--(J4=0),"")) | AP4: =IF(J4="","",--(J4=1)) | AQ4: =IF(OR($B4="",K4=""),"",--(K4=$B4)) | AR4: =IF(OR($B4="",K4=""),"",IF($B4=1,--(K4=1),"")) | AS4: =IF(OR($B4="",K4=""),"",IF($B4=0,--(K4=0),"")) | AT4: =IF(K4="","",--(K4=1)) | AU4: =IF(OR($B4="",L4=""),"",--(L4=$B4)) | AV4: =IF(OR($B4="",L4=""),"",IF($B4=1,--(L4=1),"")) | AW4: =IF(OR($B4="",L4=""),"",IF($B4=0,--(L4=0),"")) | AX4: =IF(L4="","",--(L4=1)) | AY4: =IF(OR($B4="",M4=""),"",--(M4=$B4)) | AZ4: =IF(OR($B4="",M4=""),"",IF($B4=1,--(M4=1),"")) | BA4: =IF(OR($B4="",M4=""),"",IF($B4=0,--(M4=0),"")) | BB4: =IF(M4="","",--(M4=1)) | BC4: =IF(OR($B4="",N4=""),"",--(N4=$B4)) | BD4: =IF(OR($B4="",N4=""),"",IF($B4=1,--(N4=1),"")) | BE4: =IF(OR($B4="",N4=""),"",IF($B4=0,--(N4=0),"")) | BF4: =IF(N4="","",--(N4=1))
A5: 201818910 | B5: 1 | C5: RQ | D5: 0 | E5: 0 | F5: 0 | G5: 0 | H5: 1 | I5: 0 | J5: 1 | K5: 0 | L5: 1 | M5: 1 | N5: 1 | O5: =IF(OR($B5="",D5=""),"",--(D5=$B5)) | P5: =IF(OR($B5="",D5=""),"",IF($B5=1,--(D5=1),"")) | Q5: =IF(OR($B5="",D5=""),"",IF($B5=0,--(D5=0),"")) | R5: =IF(D5="","",--(D5=1)) | S5: =IF(OR($B5="",E5=""),"",--(E5=$B5)) | T5: =IF(OR($B5="",E5=""),"",IF($B5=1,--(E5=1),"")) | U5: =IF(OR($B5="",E5=""),"",IF($B5=0,--(E5=0),"")) | V5: =IF(E5="","",--(E5=1)) | W5: =IF(OR($B5="",F5=""),"",--(F5=$B5)) | X5: =IF(OR($B5="",F5=""),"",IF($B5=1,--(F5=1),"")) | Y5: =IF(OR($B5="",F5=""),"",IF($B5=0,--(F5=0),"")) | Z5: =IF(F5="","",--(F5=1)) | AA5: =IF(OR($B5="",G5=""),"",--(G5=$B5)) | AB5: =IF(OR($B5="",G5=""),"",IF($B5=1,--(G5=1),"")) | AC5: =IF(OR($B5="",G5=""),"",IF($B5=0,--(G5=0),"")) | AD5: =IF(G5="","",--(G5=1)) | AE5: =IF(OR($B5="",H5=""),"",--(H5=$B5)) | AF5: =IF(OR($B5="",H5=""),"",IF($B5=1,--(H5=1),"")) | AG5: =IF(OR($B5="",H5=""),"",IF($B5=0,--(H5=0),"")) | AH5: =IF(H5="","",--(H5=1)) | AI5: =IF(OR($B5="",I5=""),"",--(I5=$B5)) | AJ5: =IF(OR($B5="",I5=""),"",IF($B5=1,--(I5=1),"")) | AK5: =IF(OR($B5="",I5=""),"",IF($B5=0,--(I5=0),"")) | AL5: =IF(I5="","",--(I5=1)) | AM5: =IF(OR($B5="",J5=""),"",--(J5=$B5)) | AN5: =IF(OR($B5="",J5=""),"",IF($B5=1,--(J5=1),"")) | AO5: =IF(OR($B5="",J5=""),"",IF($B5=0,--(J5=0),"")) | AP5: =IF(J5="","",--(J5=1)) | AQ5: =IF(OR($B5="",K5=""),"",--(K5=$B5)) | AR5: =IF(OR($B5="",K5=""),"",IF($B5=1,--(K5=1),"")) | AS5: =IF(OR($B5="",K5=""),"",IF($B5=0,--(K5=0),"")) | AT5: =IF(K5="","",--(K5=1)) | AU5: =IF(OR($B5="",L5=""),"",--(L5=$B5)) | AV5: =IF(OR($B5="",L5=""),"",IF($B5=1,--(L5=1),"")) | AW5: =IF(OR($B5="",L5=""),"",IF($B5=0,--(L5=0),"")) | AX5: =IF(L5="","",--(L5=1)) | AY5: =IF(OR($B5="",M5=""),"",--(M5=$B5)) | AZ5: =IF(OR($B5="",M5=""),"",IF($B5=1,--(M5=1),"")) | BA5: =IF(OR($B5="",M5=""),"",IF($B5=0,--(M5=0),"")) | BB5: =IF(M5="","",--(M5=1)) | BC5: =IF(OR($B5="",N5=""),"",--(N5=$B5)) | BD5: =IF(OR($B5="",N5=""),"",IF($B5=1,--(N5=1),"")) | BE5: =IF(OR($B5="",N5=""),"",IF($B5=0,--(N5=0),"")) | BF5: =IF(N5="","",--(N5=1))
A6: 201823477 | B6: 1 | C6: Direct | D6: 1 | E6: 1 | F6: 0 | G6: 0 | H6: 0 | I6: 1 | J6: 0 | K6: 1 | L6: 0 | M6: 0 | N6: 1 | O6: =IF(OR($B6="",D6=""),"",--(D6=$B6)) | P6: =IF(OR($B6="",D6=""),"",IF($B6=1,--(D6=1),"")) | Q6: =IF(OR($B6="",D6=""),"",IF($B6=0,--(D6=0),"")) | R6: =IF(D6="","",--(D6=1)) | S6: =IF(OR($B6="",E6=""),"",--(E6=$B6)) | T6: =IF(OR($B6="",E6=""),"",IF($B6=1,--(E6=1),"")) | U6: =IF(OR($B6="",E6=""),"",IF($B6=0,--(E6=0),"")) | V6: =IF(E6="","",--(E6=1)) | W6: =IF(OR($B6="",F6=""),"",--(F6=$B6)) | X6: =IF(OR($B6="",F6=""),"",IF($B6=1,--(F6=1),"")) | Y6: =IF(OR($B6="",F6=""),"",IF($B6=0,--(F6=0),"")) | Z6: =IF(F6="","",--(F6=1)) | AA6: =IF(OR($B6="",G6=""),"",--(G6=$B6)) | AB6: =IF(OR($B6="",G6=""),"",IF($B6=1,--(G6=1),"")) | AC6: =IF(OR($B6="",G6=""),"",IF($B6=0,--(G6=0),"")) | AD6: =IF(G6="","",--(G6=1)) | AE6: =IF(OR($B6="",H6=""),"",--(H6=$B6)) | AF6: =IF(OR($B6="",H6=""),"",IF($B6=1,--(H6=1),"")) | AG6: =IF(OR($B6="",H6=""),"",IF($B6=0,--(H6=0),"")) | AH6: =IF(H6="","",--(H6=1)) | AI6: =IF(OR($B6="",I6=""),"",--(I6=$B6)) | AJ6: =IF(OR($B6="",I6=""),"",IF($B6=1,--(I6=1),"")) | AK6: =IF(OR($B6="",I6=""),"",IF($B6=0,--(I6=0),"")) | AL6: =IF(I6="","",--(I6=1)) | AM6: =IF(OR($B6="",J6=""),"",--(J6=$B6)) | AN6: =IF(OR($B6="",J6=""),"",IF($B6=1,--(J6=1),"")) | AO6: =IF(OR($B6="",J6=""),"",IF($B6=0,--(J6=0),"")) | AP6: =IF(J6="","",--(J6=1)) | AQ6: =IF(OR($B6="",K6=""),"",--(K6=$B6)) | AR6: =IF(OR($B6="",K6=""),"",IF($B6=1,--(K6=1),"")) | AS6: =IF(OR($B6="",K6=""),"",IF($B6=0,--(K6=0),"")) | AT6: =IF(K6="","",--(K6=1)) | AU6: =IF(OR($B6="",L6=""),"",--(L6=$B6)) | AV6: =IF(OR($B6="",L6=""),"",IF($B6=1,--(L6=1),"")) | AW6: =IF(OR($B6="",L6=""),"",IF($B6=0,--(L6=0),"")) | AX6: =IF(L6="","",--(L6=1)) | AY6: =IF(OR($B6="",M6=""),"",--(M6=$B6)) | AZ6: =IF(OR($B6="",M6=""),"",IF($B6=1,--(M6=1),"")) | BA6: =IF(OR($B6="",M6=""),"",IF($B6=0,--(M6=0),"")) | BB6: =IF(M6="","",--(M6=1)) | BC6: =IF(OR($B6="",N6=""),"",--(N6=$B6)) | BD6: =IF(OR($B6="",N6=""),"",IF($B6=1,--(N6=1),"")) | BE6: =IF(OR($B6="",N6=""),"",IF($B6=0,--(N6=0),"")) | BF6: =IF(N6="","",--(N6=1))
A7: 201824266 | B7: 1 | C7: Direct | D7: 1 | E7: 1 | F7: 1 | G7: 1 | H7: 1 | I7: 1 | J7: 1 | K7: 1 | L7: 1 | M7: 1 | N7: 1 | O7: =IF(OR($B7="",D7=""),"",--(D7=$B7)) | P7: =IF(OR($B7="",D7=""),"",IF($B7=1,--(D7=1),"")) | Q7: =IF(OR($B7="",D7=""),"",IF($B7=0,--(D7=0),"")) | R7: =IF(D7="","",--(D7=1)) | S7: =IF(OR($B7="",E7=""),"",--(E7=$B7)) | T7: =IF(OR($B7="",E7=""),"",IF($B7=1,--(E7=1),"")) | U7: =IF(OR($B7="",E7=""),"",IF($B7=0,--(E7=0),"")) | V7: =IF(E7="","",--(E7=1)) | W7: =IF(OR($B7="",F7=""),"",--(F7=$B7)) | X7: =IF(OR($B7="",F7=""),"",IF($B7=1,--(F7=1),"")) | Y7: =IF(OR($B7="",F7=""),"",IF($B7=0,--(F7=0),"")) | Z7: =IF(F7="","",--(F7=1)) | AA7: =IF(OR($B7="",G7=""),"",--(G7=$B7)) | AB7: =IF(OR($B7="",G7=""),"",IF($B7=1,--(G7=1),"")) | AC7: =IF(OR($B7="",G7=""),"",IF($B7=0,--(G7=0),"")) | AD7: =IF(G7="","",--(G7=1)) | AE7: =IF(OR($B7="",H7=""),"",--(H7=$B7)) | AF7: =IF(OR($B7="",H7=""),"",IF($B7=1,--(H7=1),"")) | AG7: =IF(OR($B7="",H7=""),"",IF($B7=0,--(H7=0),"")) | AH7: =IF(H7="","",--(H7=1)) | AI7: =IF(OR($B7="",I7=""),"",--(I7=$B7)) | AJ7: =IF(OR($B7="",I7=""),"",IF($B7=1,--(I7=1),"")) | AK7: =IF(OR($B7="",I7=""),"",IF($B7=0,--(I7=0),"")) | AL7: =IF(I7="","",--(I7=1)) | AM7: =IF(OR($B7="",J7=""),"",--(J7=$B7)) | AN7: =IF(OR($B7="",J7=""),"",IF($B7=1,--(J7=1),"")) | AO7: =IF(OR($B7="",J7=""),"",IF($B7=0,--(J7=0),"")) | AP7: =IF(J7="","",--(J7=1)) | AQ7: =IF(OR($B7="",K7=""),"",--(K7=$B7)) | AR7: =IF(OR($B7="",K7=""),"",IF($B7=1,--(K7=1),"")) | AS7: =IF(OR($B7="",K7=""),"",IF($B7=0,--(K7=0),"")) | AT7: =IF(K7="","",--(K7=1)) | AU7: =IF(OR($B7="",L7=""),"",--(L7=$B7)) | AV7: =IF(OR($B7="",L7=""),"",IF($B7=1,--(L7=1),"")) | AW7: =IF(OR($B7="",L7=""),"",IF($B7=0,--(L7=0),"")) | AX7: =IF(L7="","",--(L7=1)) | AY7: =IF(OR($B7="",M7=""),"",--(M7=$B7)) | AZ7: =IF(OR($B7="",M7=""),"",IF($B7=1,--(M7=1),"")) | BA7: =IF(OR($B7="",M7=""),"",IF($B7=0,--(M7=0),"")) | BB7: =IF(M7="","",--(M7=1)) | BC7: =IF(OR($B7="",N7=""),"",--(N7=$B7)) | BD7: =IF(OR($B7="",N7=""),"",IF($B7=1,--(N7=1),"")) | BE7: =IF(OR($B7="",N7=""),"",IF($B7=0,--(N7=0),"")) | BF7: =IF(N7="","",--(N7=1))
A8: 201825425 | B8: 1 | C8: Direct | D8: 1 | E8: 0 | F8: 0 | G8: 1 | H8: 1 | I8: 1 | J8: 1 | K8: 1 | L8: 1 | M8: 1 | N8: 1 | O8: =IF(OR($B8="",D8=""),"",--(D8=$B8)) | P8: =IF(OR($B8="",D8=""),"",IF($B8=1,--(D8=1),"")) | Q8: =IF(OR($B8="",D8=""),"",IF($B8=0,--(D8=0),"")) | R8: =IF(D8="","",--(D8=1)) | S8: =IF(OR($B8="",E8=""),"",--(E8=$B8)) | T8: =IF(OR($B8="",E8=""),"",IF($B8=1,--(E8=1),"")) | U8: =IF(OR($B8="",E8=""),"",IF($B8=0,--(E8=0),"")) | V8: =IF(E8="","",--(E8=1)) | W8: =IF(OR($B8="",F8=""),"",--(F8=$B8)) | X8: =IF(OR($B8="",F8=""),"",IF($B8=1,--(F8=1),"")) | Y8: =IF(OR($B8="",F8=""),"",IF($B8=0,--(F8=0),"")) | Z8: =IF(F8="","",--(F8=1)) | AA8: =IF(OR($B8="",G8=""),"",--(G8=$B8)) | AB8: =IF(OR($B8="",G8=""),"",IF($B8=1,--(G8=1),"")) | AC8: =IF(OR($B8="",G8=""),"",IF($B8=0,--(G8=0),"")) | AD8: =IF(G8="","",--(G8=1)) | AE8: =IF(OR($B8="",H8=""),"",--(H8=$B8)) | AF8: =IF(OR($B8="",H8=""),"",IF($B8=1,--(H8=1),"")) | AG8: =IF(OR($B8="",H8=""),"",IF($B8=0,--(H8=0),"")) | AH8: =IF(H8="","",--(H8=1)) | AI8: =IF(OR($B8="",I8=""),"",--(I8=$B8)) | AJ8: =IF(OR($B8="",I8=""),"",IF($B8=1,--(I8=1),"")) | AK8: =IF(OR($B8="",I8=""),"",IF($B8=0,--(I8=0),"")) | AL8: =IF(I8="","",--(I8=1)) | AM8: =IF(OR($B8="",J8=""),"",--(J8=$B8)) | AN8: =IF(OR($B8="",J8=""),"",IF($B8=1,--(J8=1),"")) | AO8: =IF(OR($B8="",J8=""),"",IF($B8=0,--(J8=0),"")) | AP8: =IF(J8="","",--(J8=1)) | AQ8: =IF(OR($B8="",K8=""),"",--(K8=$B8)) | AR8: =IF(OR($B8="",K8=""),"",IF($B8=1,--(K8=1),"")) | AS8: =IF(OR($B8="",K8=""),"",IF($B8=0,--(K8=0),"")) | AT8: =IF(K8="","",--(K8=1)) | AU8: =IF(OR($B8="",L8=""),"",--(L8=$B8)) | AV8: =IF(OR($B8="",L8=""),"",IF($B8=1,--(L8=1),"")) | AW8: =IF(OR($B8="",L8=""),"",IF($B8=0,--(L8=0),"")) | AX8: =IF(L8="","",--(L8=1)) | AY8: =IF(OR($B8="",M8=""),"",--(M8=$B8)) | AZ8: =IF(OR($B8="",M8=""),"",IF($B8=1,--(M8=1),"")) | BA8: =IF(OR($B8="",M8=""),"",IF($B8=0,--(M8=0),"")) | BB8: =IF(M8="","",--(M8=1)) | BC8: =IF(OR($B8="",N8=""),"",--(N8=$B8)) | BD8: =IF(OR($B8="",N8=""),"",IF($B8=1,--(N8=1),"")) | BE8: =IF(OR($B8="",N8=""),"",IF($B8=0,--(N8=0),"")) | BF8: =IF(N8="","",--(N8=1))
A9: 201827830 | B9: 0 | C9: Direct | D9: 0 | E9: 1 | F9: 0 | G9: 0 | H9: 0 | I9: 1 | J9: 1 | K9: 1 | L9: 1 | M9: 1 | N9: 1 | O9: =IF(OR($B9="",D9=""),"",--(D9=$B9)) | P9: =IF(OR($B9="",D9=""),"",IF($B9=1,--(D9=1),"")) | Q9: =IF(OR($B9="",D9=""),"",IF($B9=0,--(D9=0),"")) | R9: =IF(D9="","",--(D9=1)) | S9: =IF(OR($B9="",E9=""),"",--(E9=$B9)) | T9: =IF(OR($B9="",E9=""),"",IF($B9=1,--(E9=1),"")) | U9: =IF(OR($B9="",E9=""),"",IF($B9=0,--(E9=0),"")) | V9: =IF(E9="","",--(E9=1)) | W9: =IF(OR($B9="",F9=""),"",--(F9=$B9)) | X9: =IF(OR($B9="",F9=""),"",IF($B9=1,--(F9=1),"")) | Y9: =IF(OR($B9="",F9=""),"",IF($B9=0,--(F9=0),"")) | Z9: =IF(F9="","",--(F9=1)) | AA9: =IF(OR($B9="",G9=""),"",--(G9=$B9)) | AB9: =IF(OR($B9="",G9=""),"",IF($B9=1,--(G9=1),"")) | AC9: =IF(OR($B9="",G9=""),"",IF($B9=0,--(G9=0),"")) | AD9: =IF(G9="","",--(G9=1)) | AE9: =IF(OR($B9="",H9=""),"",--(H9=$B9)) | AF9: =IF(OR($B9="",H9=""),"",IF($B9=1,--(H9=1),"")) | AG9: =IF(OR($B9="",H9=""),"",IF($B9=0,--(H9=0),"")) | AH9: =IF(H9="","",--(H9=1)) | AI9: =IF(OR($B9="",I9=""),"",--(I9=$B9)) | AJ9: =IF(OR($B9="",I9=""),"",IF($B9=1,--(I9=1),"")) | AK9: =IF(OR($B9="",I9=""),"",IF($B9=0,--(I9=0),"")) | AL9: =IF(I9="","",--(I9=1)) | AM9: =IF(OR($B9="",J9=""),"",--(J9=$B9)) | AN9: =IF(OR($B9="",J9=""),"",IF($B9=1,--(J9=1),"")) | AO9: =IF(OR($B9="",J9=""),"",IF($B9=0,--(J9=0),"")) | AP9: =IF(J9="","",--(J9=1)) | AQ9: =IF(OR($B9="",K9=""),"",--(K9=$B9)) | AR9: =IF(OR($B9="",K9=""),"",IF($B9=1,--(K9=1),"")) | AS9: =IF(OR($B9="",K9=""),"",IF($B9=0,--(K9=0),"")) | AT9: =IF(K9="","",--(K9=1)) | AU9: =IF(OR($B9="",L9=""),"",--(L9=$B9)) | AV9: =IF(OR($B9="",L9=""),"",IF($B9=1,--(L9=1),"")) | AW9: =IF(OR($B9="",L9=""),"",IF($B9=0,--(L9=0),"")) | AX9: =IF(L9="","",--(L9=1)) | AY9: =IF(OR($B9="",M9=""),"",--(M9=$B9)) | AZ9: =IF(OR($B9="",M9=""),"",IF($B9=1,--(M9=1),"")) | BA9: =IF(OR($B9="",M9=""),"",IF($B9=0,--(M9=0),"")) | BB9: =IF(M9="","",--(M9=1)) | BC9: =IF(OR($B9="",N9=""),"",--(N9=$B9)) | BD9: =IF(OR($B9="",N9=""),"",IF($B9=1,--(N9=1),"")) | BE9: =IF(OR($B9="",N9=""),"",IF($B9=0,--(N9=0),"")) | BF9: =IF(N9="","",--(N9=1))
A10: 201837949 | B10: 1 | C10: Direct | D10: 1 | E10: 0 | F10: 0 | G10: 1 | H10: 1 | I10: 1 | J10: 1 | K10: 1 | L10: 1 | M10: 1 | N10: 1 | O10: =IF(OR($B10="",D10=""),"",--(D10=$B10)) | P10: =IF(OR($B10="",D10=""),"",IF($B10=1,--(D10=1),"")) | Q10: =IF(OR($B10="",D10=""),"",IF($B10=0,--(D10=0),"")) | R10: =IF(D10="","",--(D10=1)) | S10: =IF(OR($B10="",E10=""),"",--(E10=$B10)) | T10: =IF(OR($B10="",E10=""),"",IF($B10=1,--(E10=1),"")) | U10: =IF(OR($B10="",E10=""),"",IF($B10=0,--(E10=0),"")) | V10: =IF(E10="","",--(E10=1)) | W10: =IF(OR($B10="",F10=""),"",--(F10=$B10)) | X10: =IF(OR($B10="",F10=""),"",IF($B10=1,--(F10=1),"")) | Y10: =IF(OR($B10="",F10=""),"",IF($B10=0,--(F10=0),"")) | Z10: =IF(F10="","",--(F10=1)) | AA10: =IF(OR($B10="",G10=""),"",--(G10=$B10)) | AB10: =IF(OR($B10="",G10=""),"",IF($B10=1,--(G10=1),"")) | AC10: =IF(OR($B10="",G10=""),"",IF($B10=0,--(G10=0),"")) | AD10: =IF(G10="","",--(G10=1)) | AE10: =IF(OR($B10="",H10=""),"",--(H10=$B10)) | AF10: =IF(OR($B10="",H10=""),"",IF($B10=1,--(H10=1),"")) | AG10: =IF(OR($B10="",H10=""),"",IF($B10=0,--(H10=0),"")) | AH10: =IF(H10="","",--(H10=1)) | AI10: =IF(OR($B10="",I10=""),"",--(I10=$B10)) | AJ10: =IF(OR($B10="",I10=""),"",IF($B10=1,--(I10=1),"")) | AK10: =IF(OR($B10="",I10=""),"",IF($B10=0,--(I10=0),"")) | AL10: =IF(I10="","",--(I10=1)) | AM10: =IF(OR($B10="",J10=""),"",--(J10=$B10)) | AN10: =IF(OR($B10="",J10=""),"",IF($B10=1,--(J10=1),"")) | AO10: =IF(OR($B10="",J10=""),"",IF($B10=0,--(J10=0),"")) | AP10: =IF(J10="","",--(J10=1)) | AQ10: =IF(OR($B10="",K10=""),"",--(K10=$B10)) | AR10: =IF(OR($B10="",K10=""),"",IF($B10=1,--(K10=1),"")) | AS10: =IF(OR($B10="",K10=""),"",IF($B10=0,--(K10=0),"")) | AT10: =IF(K10="","",--(K10=1)) | AU10: =IF(OR($B10="",L10=""),"",--(L10=$B10)) | AV10: =IF(OR($B10="",L10=""),"",IF($B10=1,--(L10=1),"")) | AW10: =IF(OR($B10="",L10=""),"",IF($B10=0,--(L10=0),"")) | AX10: =IF(L10="","",--(L10=1)) | AY10: =IF(OR($B10="",M10=""),"",--(M10=$B10)) | AZ10: =IF(OR($B10="",M10=""),"",IF($B10=1,--(M10=1),"")) | BA10: =IF(OR($B10="",M10=""),"",IF($B10=0,--(M10=0),"")) | BB10: =IF(M10="","",--(M10=1)) | BC10: =IF(OR($B10="",N10=""),"",--(N10=$B10)) | BD10: =IF(OR($B10="",N10=""),"",IF($B10=1,--(N10=1),"")) | BE10: =IF(OR($B10="",N10=""),"",IF($B10=0,--(N10=0),"")) | BF10: =IF(N10="","",--(N10=1))
A11: 201912951 | B11: 0 | C11: Direct | D11: 0 | E11: 0 | F11: 0 | G11: 0 | H11: 0 | I11: 0 | J11: 0 | K11: 0 | L11: 0 | M11: 1 | N11: 0 | O11: =IF(OR($B11="",D11=""),"",--(D11=$B11)) | P11: =IF(OR($B11="",D11=""),"",IF($B11=1,--(D11=1),"")) | Q11: =IF(OR($B11="",D11=""),"",IF($B11=0,--(D11=0),"")) | R11: =IF(D11="","",--(D11=1)) | S11: =IF(OR($B11="",E11=""),"",--(E11=$B11)) | T11: =IF(OR($B11="",E11=""),"",IF($B11=1,--(E11=1),"")) | U11: =IF(OR($B11="",E11=""),"",IF($B11=0,--(E11=0),"")) | V11: =IF(E11="","",--(E11=1)) | W11: =IF(OR($B11="",F11=""),"",--(F11=$B11)) | X11: =IF(OR($B11="",F11=""),"",IF($B11=1,--(F11=1),"")) | Y11: =IF(OR($B11="",F11=""),"",IF($B11=0,--(F11=0),"")) | Z11: =IF(F11="","",--(F11=1)) | AA11: =IF(OR($B11="",G11=""),"",--(G11=$B11)) | AB11: =IF(OR($B11="",G11=""),"",IF($B11=1,--(G11=1),"")) | AC11: =IF(OR($B11="",G11=""),"",IF($B11=0,--(G11=0),"")) | AD11: =IF(G11="","",--(G11=1)) | AE11: =IF(OR($B11="",H11=""),"",--(H11=$B11)) | AF11: =IF(OR($B11="",H11=""),"",IF($B11=1,--(H11=1),"")) | AG11: =IF(OR($B11="",H11=""),"",IF($B11=0,--(H11=0),"")) | AH11: =IF(H11="","",--(H11=1)) | AI11: =IF(OR($B11="",I11=""),"",--(I11=$B11)) | AJ11: =IF(OR($B11="",I11=""),"",IF($B11=1,--(I11=1),"")) | AK11: =IF(OR($B11="",I11=""),"",IF($B11=0,--(I11=0),"")) | AL11: =IF(I11="","",--(I11=1)) | AM11: =IF(OR($B11="",J11=""),"",--(J11=$B11)) | AN11: =IF(OR($B11="",J11=""),"",IF($B11=1,--(J11=1),"")) | AO11: =IF(OR($B11="",J11=""),"",IF($B11=0,--(J11=0),"")) | AP11: =IF(J11="","",--(J11=1)) | AQ11: =IF(OR($B11="",K11=""),"",--(K11=$B11)) | AR11: =IF(OR($B11="",K11=""),"",IF($B11=1,--(K11=1),"")) | AS11: =IF(OR($B11="",K11=""),"",IF($B11=0,--(K11=0),"")) | AT11: =IF(K11="","",--(K11=1)) | AU11: =IF(OR($B11="",L11=""),"",--(L11=$B11)) | AV11: =IF(OR($B11="",L11=""),"",IF($B11=1,--(L11=1),"")) | AW11: =IF(OR($B11="",L11=""),"",IF($B11=0,--(L11=0),"")) | AX11: =IF(L11="","",--(L11=1)) | AY11: =IF(OR($B11="",M11=""),"",--(M11=$B11)) | AZ11: =IF(OR($B11="",M11=""),"",IF($B11=1,--(M11=1),"")) | BA11: =IF(OR($B11="",M11=""),"",IF($B11=0,--(M11=0),"")) | BB11: =IF(M11="","",--(M11=1)) | BC11: =IF(OR($B11="",N11=""),"",--(N11=$B11)) | BD11: =IF(OR($B11="",N11=""),"",IF($B11=1,--(N11=1),"")) | BE11: =IF(OR($B11="",N11=""),"",IF($B11=0,--(N11=0),"")) | BF11: =IF(N11="","",--(N11=1))
A12: 201913964 | B12: 0 | C12: Direct | D12: 1 | E12: 1 | F12: 0 | G12: 0 | H12: 0 | I12: 0 | J12: 1 | K12: 1 | L12: 1 | M12: 1 | N12: 1 | O12: =IF(OR($B12="",D12=""),"",--(D12=$B12)) | P12: =IF(OR($B12="",D12=""),"",IF($B12=1,--(D12=1),"")) | Q12: =IF(OR($B12="",D12=""),"",IF($B12=0,--(D12=0),"")) | R12: =IF(D12="","",--(D12=1)) | S12: =IF(OR($B12="",E12=""),"",--(E12=$B12)) | T12: =IF(OR($B12="",E12=""),"",IF($B12=1,--(E12=1),"")) | U12: =IF(OR($B12="",E12=""),"",IF($B12=0,--(E12=0),"")) | V12: =IF(E12="","",--(E12=1)) | W12: =IF(OR($B12="",F12=""),"",--(F12=$B12)) | X12: =IF(OR($B12="",F12=""),"",IF($B12=1,--(F12=1),"")) | Y12: =IF(OR($B12="",F12=""),"",IF($B12=0,--(F12=0),"")) | Z12: =IF(F12="","",--(F12=1)) | AA12: =IF(OR($B12="",G12=""),"",--(G12=$B12)) | AB12: =IF(OR($B12="",G12=""),"",IF($B12=1,--(G12=1),"")) | AC12: =IF(OR($B12="",G12=""),"",IF($B12=0,--(G12=0),"")) | AD12: =IF(G12="","",--(G12=1)) | AE12: =IF(OR($B12="",H12=""),"",--(H12=$B12)) | AF12: =IF(OR($B12="",H12=""),"",IF($B12=1,--(H12=1),"")) | AG12: =IF(OR($B12="",H12=""),"",IF($B12=0,--(H12=0),"")) | AH12: =IF(H12="","",--(H12=1)) | AI12: =IF(OR($B12="",I12=""),"",--(I12=$B12)) | AJ12: =IF(OR($B12="",I12=""),"",IF($B12=1,--(I12=1),"")) | AK12: =IF(OR($B12="",I12=""),"",IF($B12=0,--(I12=0),"")) | AL12: =IF(I12="","",--(I12=1)) | AM12: =IF(OR($B12="",J12=""),"",--(J12=$B12)) | AN12: =IF(OR($B12="",J12=""),"",IF($B12=1,--(J12=1),"")) | AO12: =IF(OR($B12="",J12=""),"",IF($B12=0,--(J12=0),"")) | AP12: =IF(J12="","",--(J12=1)) | AQ12: =IF(OR($B12="",K12=""),"",--(K12=$B12)) | AR12: =IF(OR($B12="",K12=""),"",IF($B12=1,--(K12=1),"")) | AS12: =IF(OR($B12="",K12=""),"",IF($B12=0,--(K12=0),"")) | AT12: =IF(K12="","",--(K12=1)) | AU12: =IF(OR($B12="",L12=""),"",--(L12=$B12)) | AV12: =IF(OR($B12="",L12=""),"",IF($B12=1,--(L12=1),"")) | AW12: =IF(OR($B12="",L12=""),"",IF($B12=0,--(L12=0),"")) | AX12: =IF(L12="","",--(L12=1)) | AY12: =IF(OR($B12="",M12=""),"",--(M12=$B12)) | AZ12: =IF(OR($B12="",M12=""),"",IF($B12=1,--(M12=1),"")) | BA12: =IF(OR($B12="",M12=""),"",IF($B12=0,--(M12=0),"")) | BB12: =IF(M12="","",--(M12=1)) | BC12: =IF(OR($B12="",N12=""),"",--(N12=$B12)) | BD12: =IF(OR($B12="",N12=""),"",IF($B12=1,--(N12=1),"")) | BE12: =IF(OR($B12="",N12=""),"",IF($B12=0,--(N12=0),"")) | BF12: =IF(N12="","",--(N12=1))
A13: 201914739 | B13: 1 | C13: Direct | D13: 1 | E13: 1 | F13: 1 | G13: 1 | H13: 1 | I13: 1 | J13: 0 | K13: 1 | L13: 1 | M13: 1 | N13: 1 | O13: =IF(OR($B13="",D13=""),"",--(D13=$B13)) | P13: =IF(OR($B13="",D13=""),"",IF($B13=1,--(D13=1),"")) | Q13: =IF(OR($B13="",D13=""),"",IF($B13=0,--(D13=0),"")) | R13: =IF(D13="","",--(D13=1)) | S13: =IF(OR($B13="",E13=""),"",--(E13=$B13)) | T13: =IF(OR($B13="",E13=""),"",IF($B13=1,--(E13=1),"")) | U13: =IF(OR($B13="",E13=""),"",IF($B13=0,--(E13=0),"")) | V13: =IF(E13="","",--(E13=1)) | W13: =IF(OR($B13="",F13=""),"",--(F13=$B13)) | X13: =IF(OR($B13="",F13=""),"",IF($B13=1,--(F13=1),"")) | Y13: =IF(OR($B13="",F13=""),"",IF($B13=0,--(F13=0),"")) | Z13: =IF(F13="","",--(F13=1)) | AA13: =IF(OR($B13="",G13=""),"",--(G13=$B13)) | AB13: =IF(OR($B13="",G13=""),"",IF($B13=1,--(G13=1),"")) | AC13: =IF(OR($B13="",G13=""),"",IF($B13=0,--(G13=0),"")) | AD13: =IF(G13="","",--(G13=1)) | AE13: =IF(OR($B13="",H13=""),"",--(H13=$B13)) | AF13: =IF(OR($B13="",H13=""),"",IF($B13=1,--(H13=1),"")) | AG13: =IF(OR($B13="",H13=""),"",IF($B13=0,--(H13=0),"")) | AH13: =IF(H13="","",--(H13=1)) | AI13: =IF(OR($B13="",I13=""),"",--(I13=$B13)) | AJ13: =IF(OR($B13="",I13=""),"",IF($B13=1,--(I13=1),"")) | AK13: =IF(OR($B13="",I13=""),"",IF($B13=0,--(I13=0),"")) | AL13: =IF(I13="","",--(I13=1)) | AM13: =IF(OR($B13="",J13=""),"",--(J13=$B13)) | AN13: =IF(OR($B13="",J13=""),"",IF($B13=1,--(J13=1),"")) | AO13: =IF(OR($B13="",J13=""),"",IF($B13=0,--(J13=0),"")) | AP13: =IF(J13="","",--(J13=1)) | AQ13: =IF(OR($B13="",K13=""),"",--(K13=$B13)) | AR13: =IF(OR($B13="",K13=""),"",IF($B13=1,--(K13=1),"")) | AS13: =IF(OR($B13="",K13=""),"",IF($B13=0,--(K13=0),"")) | AT13: =IF(K13="","",--(K13=1)) | AU13: =IF(OR($B13="",L13=""),"",--(L13=$B13)) | AV13: =IF(OR($B13="",L13=""),"",IF($B13=1,--(L13=1),"")) | AW13: =IF(OR($B13="",L13=""),"",IF($B13=0,--(L13=0),"")) | AX13: =IF(L13="","",--(L13=1)) | AY13: =IF(OR($B13="",M13=""),"",--(M13=$B13)) | AZ13: =IF(OR($B13="",M13=""),"",IF($B13=1,--(M13=1),"")) | BA13: =IF(OR($B13="",M13=""),"",IF($B13=0,--(M13=0),"")) | BB13: =IF(M13="","",--(M13=1)) | BC13: =IF(OR($B13="",N13=""),"",--(N13=$B13)) | BD13: =IF(OR($B13="",N13=""),"",IF($B13=1,--(N13=1),"")) | BE13: =IF(OR($B13="",N13=""),"",IF($B13=0,--(N13=0),"")) | BF13: =IF(N13="","",--(N13=1))
... A501: 20246350 | B501: 0 | C501: Direct | D501: 1 | E501: 0 | F501: 0 | G501: 0 | H501: 0 | I501: 0 | J501: 0 | K501: 0 | L501: 0 | M501: 0 | N501: 0 | O501: =IF(OR($B501="",D501=""),"",--(D501=$B501)) | P501: =IF(OR($B501="",D501=""),"",IF($B501=1,--(D501=1),"")) | Q501: =IF(OR($B501="",D501=""),"",IF($B501=0,--(D501=0),"")) | R501: =IF(D501="","",--(D501=1)) | S501: =IF(OR($B501="",E501=""),"",--(E501=$B501)) | T501: =IF(OR($B501="",E501=""),"",IF($B501=1,--(E501=1),"")) | U501: =IF(OR($B501="",E501=""),"",IF($B501=0,--(E501=0),"")) | V501: =IF(E501="","",--(E501=1)) | W501: =IF(OR($B501="",F501=""),"",--(F501=$B501)) | X501: =IF(OR($B501="",F501=""),"",IF($B501=1,--(F501=1),"")) | Y501: =IF(OR($B501="",F501=""),"",IF($B501=0,--(F501=0),"")) | Z501: =IF(F501="","",--(F501=1)) | AA501: =IF(OR($B501="",G501=""),"",--(G501=$B501)) | AB501: =IF(OR($B501="",G501=""),"",IF($B501=1,--(G501=1),"")) | AC501: =IF(OR($B501="",G501=""),"",IF($B501=0,--(G501=0),"")) | AD501: =IF(G501="","",--(G501=1)) | AE501: =IF(OR($B501="",H501=""),"",--(H501=$B501)) | AF501: =IF(OR($B501="",H501=""),"",IF($B501=1,--(H501=1),"")) | AG501: =IF(OR($B501="",H501=""),"",IF($B501=0,--(H501=0),"")) | AH501: =IF(H501="","",--(H501=1)) | AI501: =IF(OR($B501="",I501=""),"",--(I501=$B501)) | AJ501: =IF(OR($B501="",I501=""),"",IF($B501=1,--(I501=1),"")) | AK501: =IF(OR($B501="",I501=""),"",IF($B501=0,--(I501=0),"")) | AL501: =IF(I501="","",--(I501=1)) | AM501: =IF(OR($B501="",J501=""),"",--(J501=$B501)) | AN501: =IF(OR($B501="",J501=""),"",IF($B501=1,--(J501=1),"")) | AO501: =IF(OR($B501="",J501=""),"",IF($B501=0,--(J501=0),"")) | AP501: =IF(J501="","",--(J501=1)) | AQ501: =IF(OR($B501="",K501=""),"",--(K501=$B501)) | AR501: =IF(OR($B501="",K501=""),"",IF($B501=1,--(K501=1),"")) | AS501: =IF(OR($B501="",K501=""),"",IF($B501=0,--(K501=0),"")) | AT501: =IF(K501="","",--(K501=1)) | AU501: =IF(OR($B501="",L501=""),"",--(L501=$B501)) | AV501: =IF(OR($B501="",L501=""),"",IF($B501=1,--(L501=1),"")) | AW501: =IF(OR($B501="",L501=""),"",IF($B501=0,--(L501=0),"")) | AX501: =IF(L501="","",--(L501=1)) | AY501: =IF(OR($B501="",M501=""),"",--(M501=$B501)) | AZ501: =IF(OR($B501="",M501=""),"",IF($B501=1,--(M501=1),"")) | BA501: =IF(OR($B501="",M501=""),"",IF($B501=0,--(M501=0),"")) | BB501: =IF(M501="","",--(M501=1)) | BC501: =IF(OR($B501="",N501=""),"",--(N501=$B501)) | BD501: =IF(OR($B501="",N501=""),"",IF($B501=1,--(N501=1),"")) | BE501: =IF(OR($B501="",N501=""),"",IF($B501=0,--(N501=0),"")) | BF501: =IF(N501="","",--(N501=1))

Sheet mcnemar_overall
A1: comparison_id | B1: family_id | C1: subset | D1: system_A | E1: system_B | F1: n_paired_cases | G1: n11_both_correct | H1: n10_A_correct_B_wrong | I1: n01_A_wrong_B_correct | J1: n00_both_wrong | K1: delta_accuracy | L1: exact_mcnemar_p_raw | M1: exact_mcnemar_p_holm
A2: LoTT_vs_G20_Std_full500 | B2: A_full500 | C2: full500 | D2: lott_framework | E2: g20_standard | F2: =COUNTIFS(case_predictions_full500!$B$2:$B$501,"<>",case_predictions_full500!$D$2:$D$501,"<>",case_predictions_full500!$F$2:$F$501,"<>") | G2: =COUNTIFS(case_predictions_full500!$O$2:$O$501,1,case_predictions_full500!$W$2:$W$501,1) | H2: =COUNTIFS(case_predictions_full500!$O$2:$O$501,1,case_predictions_full500!$W$2:$W$501,0) | I2: =COUNTIFS(case_predictions_full500!$O$2:$O$501,0,case_predictions_full500!$W$2:$W$501,1) | J2: =IF(F2=0,"",F2-G2-H2-I2) | K2: =IF(F2=0,"",(H2-I2)/F2) | L2: =IF(H2+I2=0,"",MIN(1,2*_xludf.BINOM.DIST(MIN(H2,I2),H2+I2,0.5,TRUE))) | M2: =IF(L2="","",MIN(1,MAX(SMALL($L$2:$L$4,1)*3,IF(_xludf.RANK.EQ(L2,$L$2:$L$4,1)>=2,SMALL($L$2:$L$4,2)*2,0),IF(_xludf.RANK.EQ(L2,$L$2:$L$4,1)>=3,SMALL($L$2:$L$4,3)*1,0))))
A3: LoTT_vs_G20_CoT_full500 | B3: A_full500 | C3: full500 | D3: lott_framework | E3: g20_cot | F3: =COUNTIFS(case_predictions_full500!$B$2:$B$501,"<>",case_predictions_full500!$D$2:$D$501,"<>",case_predictions_full500!$G$2:$G$501,"<>") | G3: =COUNTIFS(case_predictions_full500!$O$2:$O$501,1,case_predictions_full500!$AA$2:$AA$501,1) | H3: =COUNTIFS(case_predictions_full500!$O$2:$O$501,1,case_predictions_full500!$AA$2:$AA$501,0) | I3: =COUNTIFS(case_predictions_full500!$O$2:$O$501,0,case_predictions_full500!$AA$2:$AA$501,1) | J3: =IF(F3=0,"",F3-G3-H3-I3) | K3: =IF(F3=0,"",(H3-I3)/F3) | L3: =IF(H3+I3=0,"",MIN(1,2*_xludf.BINOM.DIST(MIN(H3,I3),H3+I3,0.5,TRUE))) | M3: =IF(L3="","",MIN(1,MAX(SMALL($L$2:$L$4,1)*3,IF(_xludf.RANK.EQ(L3,$L$2:$L$4,1)>=2,SMALL($L$2:$L$4,2)*2,0),IF(_xludf.RANK.EQ(L3,$L$2:$L$4,1)>=3,SMALL($L$2:$L$4,3)*1,0))))
A4: LoTT_vs_G20_LS_full500 | B4: A_full500 | C4: full500 | D4: lott_framework | E4: g20_ls | F4: =COUNTIFS(case_predictions_full500!$B$2:$B$501,"<>",case_predictions_full500!$D$2:$D$501,"<>",case_predictions_full500!$H$2:$H$501,"<>") | G4: =COUNTIFS(case_predictions_full500!$O$2:$O$501,1,case_predictions_full500!$AE$2:$AE$501,1) | H4: =COUNTIFS(case_predictions_full500!$O$2:$O$501,1,case_predictions_full500!$AE$2:$AE$501,0) | I4: =COUNTIFS(case_predictions_full500!$O$2:$O$501,0,case_predictions_full500!$AE$2:$AE$501,1) | J4: =IF(F4=0,"",F4-G4-H4-I4) | K4: =IF(F4=0,"",(H4-I4)/F4) | L4: =IF(H4+I4=0,"",MIN(1,2*_xludf.BINOM.DIST(MIN(H4,I4),H4+I4,0.5,TRUE))) | M4: =IF(L4="","",MIN(1,MAX(SMALL($L$2:$L$4,1)*3,IF(_xludf.RANK.EQ(L4,$L$2:$L$4,1)>=2,SMALL($L$2:$L$4,2)*2,0),IF(_xludf.RANK.EQ(L4,$L$2:$L$4,1)>=3,SMALL($L$2:$L$4,3)*1,0))))
A5: RQ_vs_G20_Std_full500 | B5: B_full500 | C5: full500 | D5: rq_all500 | E5: g20_standard | F5: =COUNTIFS(case_predictions_full500!$B$2:$B$501,"<>",case_predictions_full500!$E$2:$E$501,"<>",case_predictions_full500!$F$2:$F$501,"<>") | G5: =COUNTIFS(case_predictions_full500!$S$2:$S$501,1,case_predictions_full500!$W$2:$W$501,1) | H5: =COUNTIFS(case_predictions_full500!$S$2:$S$501,1,case_predictions_full500!$W$2:$W$501,0) | I5: =COUNTIFS(case_predictions_full500!$S$2:$S$501,0,case_predictions_full500!$W$2:$W$501,1) | J5: =IF(F5=0,"",F5-G5-H5-I5) | K5: =IF(F5=0,"",(H5-I5)/F5) | L5: =IF(H5+I5=0,"",MIN(1,2*_xludf.BINOM.DIST(MIN(H5,I5),H5+I5,0.5,TRUE))) | M5: =IF(L5="","",MIN(1,MAX(SMALL($L$5:$L$7,1)*3,IF(_xludf.RANK.EQ(L5,$L$5:$L$7,1)>=2,SMALL($L$5:$L$7,2)*2,0),IF(_xludf.RANK.EQ(L5,$L$5:$L$7,1)>=3,SMALL($L$5:$L$7,3)*1,0))))
A6: RQ_vs_G20_CoT_full500 | B6: B_full500 | C6: full500 | D6: rq_all500 | E6: g20_cot | F6: =COUNTIFS(case_predictions_full500!$B$2:$B$501,"<>",case_predictions_full500!$E$2:$E$501,"<>",case_predictions_full500!$G$2:$G$501,"<>") | G6: =COUNTIFS(case_predictions_full500!$S$2:$S$501,1,case_predictions_full500!$AA$2:$AA$501,1) | H6: =COUNTIFS(case_predictions_full500!$S$2:$S$501,1,case_predictions_full500!$AA$2:$AA$501,0) | I6: =COUNTIFS(case_predictions_full500!$S$2:$S$501,0,case_predictions_full500!$AA$2:$AA$501,1) | J6: =IF(F6=0,"",F6-G6-H6-I6) | K6: =IF(F6=0,"",(H6-I6)/F6) | L6: =IF(H6+I6=0,"",MIN(1,2*_xludf.BINOM.DIST(MIN(H6,I6),H6+I6,0.5,TRUE))) | M6: =IF(L6="","",MIN(1,MAX(SMALL($L$5:$L$7,1)*3,IF(_xludf.RANK.EQ(L6,$L$5:$L$7,1)>=2,SMALL($L$5:$L$7,2)*2,0),IF(_xludf.RANK.EQ(L6,$L$5:$L$7,1)>=3,SMALL($L$5:$L$7,3)*1,0))))
A7: RQ_vs_G20_LS_full500 | B7: B_full500 | C7: full500 | D7: rq_all500 | E7: g20_ls | F7: =COUNTIFS(case_predictions_full500!$B$2:$B$501,"<>",case_predictions_full500!$E$2:$E$501,"<>",case_predictions_full500!$H$2:$H$501,"<>") | G7: =COUNTIFS(case_predictions_full500!$S$2:$S$501,1,case_predictions_full500!$AE$2:$AE$501,1) | H7: =COUNTIFS(case_predictions_full500!$S$2:$S$501,1,case_predictions_full500!$AE$2:$AE$501,0) | I7: =COUNTIFS(case_predictions_full500!$S$2:$S$501,0,case_predictions_full500!$AE$2:$AE$501,1) | J7: =IF(F7=0,"",F7-G7-H7-I7) | K7: =IF(F7=0,"",(H7-I7)/F7) | L7: =IF(H7+I7=0,"",MIN(1,2*_xludf.BINOM.DIST(MIN(H7,I7),H7+I7,0.5,TRUE))) | M7: =IF(L7="","",MIN(1,MAX(SMALL($L$5:$L$7,1)*3,IF(_xludf.RANK.EQ(L7,$L$5:$L$7,1)>=2,SMALL($L$5:$L$7,2)*2,0),IF(_xludf.RANK.EQ(L7,$L$5:$L$7,1)>=3,SMALL($L$5:$L$7,3)*1,0))))
A8: LoTT_vs_G20_Std_direct477 | B8: C_direct477 | C8: direct477 | D8: lott_framework | E8: g20_standard | F8: =COUNTIFS(case_predictions_full500!$B$2:$B$501,"<>",case_predictions_full500!$D$2:$D$501,"<>",case_predictions_full500!$F$2:$F$501,"<>",case_predictions_full500!$C$2:$C$501,"Direct") | G8: =COUNTIFS(case_predictions_full500!$O$2:$O$501,1,case_predictions_full500!$W$2:$W$501,1,case_predictions_full500!$C$2:$C$501,"Direct") | H8: =COUNTIFS(case_predictions_full500!$O$2:$O$501,1,case_predictions_full500!$W$2:$W$501,0,case_predictions_full500!$C$2:$C$501,"Direct") | I8: =COUNTIFS(case_predictions_full500!$O$2:$O$501,0,case_predictions_full500!$W$2:$W$501,1,case_predictions_full500!$C$2:$C$501,"Direct") | J8: =IF(F8=0,"",F8-G8-H8-I8) | K8: =IF(F8=0,"",(H8-I8)/F8) | L8: =IF(H8+I8=0,"",MIN(1,2*_xludf.BINOM.DIST(MIN(H8,I8),H8+I8,0.5,TRUE))) | M8: =IF(L8="","",MIN(1,MAX(SMALL($L$8:$L$10,1)*3,IF(_xludf.RANK.EQ(L8,$L$8:$L$10,1)>=2,SMALL($L$8:$L$10,2)*2,0),IF(_xludf.RANK.EQ(L8,$L$8:$L$10,1)>=3,SMALL($L$8:$L$10,3)*1,0))))
A9: LoTT_vs_G20_CoT_direct477 | B9: C_direct477 | C9: direct477 | D9: lott_framework | E9: g20_cot | F9: =COUNTIFS(case_predictions_full500!$B$2:$B$501,"<>",case_predictions_full500!$D$2:$D$501,"<>",case_predictions_full500!$G$2:$G$501,"<>",case_predictions_full500!$C$2:$C$501,"Direct") | G9: =COUNTIFS(case_predictions_full500!$O$2:$O$501,1,case_predictions_full500!$AA$2:$AA$501,1,case_predictions_full500!$C$2:$C$501,"Direct") | H9: =COUNTIFS(case_predictions_full500!$O$2:$O$501,1,case_predictions_full500!$AA$2:$AA$501,0,case_predictions_full500!$C$2:$C$501,"Direct") | I9: =COUNTIFS(case_predictions_full500!$O$2:$O$501,0,case_predictions_full500!$AA$2:$AA$501,1,case_predictions_full500!$C$2:$C$501,"Direct") | J9: =IF(F9=0,"",F9-G9-H9-I9) | K9: =IF(F9=0,"",(H9-I9)/F9) | L9: =IF(H9+I9=0,"",MIN(1,2*_xludf.BINOM.DIST(MIN(H9,I9),H9+I9,0.5,TRUE))) | M9: =IF(L9="","",MIN(1,MAX(SMALL($L$8:$L$10,1)*3,IF(_xludf.RANK.EQ(L9,$L$8:$L$10,1)>=2,SMALL($L$8:$L$10,2)*2,0),IF(_xludf.RANK.EQ(L9,$L$8:$L$10,1)>=3,SMALL($L$8:$L$10,3)*1,0))))
A10: LoTT_vs_G20_LS_direct477 | B10: C_direct477 | C10: direct477 | D10: lott_framework | E10: g20_ls | F10: =COUNTIFS(case_predictions_full500!$B$2:$B$501,"<>",case_predictions_full500!$D$2:$D$501,"<>",case_predictions_full500!$H$2:$H$501,"<>",case_predictions_full500!$C$2:$C$501,"Direct") | G10: =COUNTIFS(case_predictions_full500!$O$2:$O$501,1,case_predictions_full500!$AE$2:$AE$501,1,case_predictions_full500!$C$2:$C$501,"Direct") | H10: =COUNTIFS(case_predictions_full500!$O$2:$O$501,1,case_predictions_full500!$AE$2:$AE$501,0,case_predictions_full500!$C$2:$C$501,"Direct") | I10: =COUNTIFS(case_predictions_full500!$O$2:$O$501,0,case_predictions_full500!$AE$2:$AE$501,1,case_predictions_full500!$C$2:$C$501,"Direct") | J10: =IF(F10=0,"",F10-G10-H10-I10) | K10: =IF(F10=0,"",(H10-I10)/F10) | L10: =IF(H10+I10=0,"",MIN(1,2*_xludf.BINOM.DIST(MIN(H10,I10),H10+I10,0.5,TRUE))) | M10: =IF(L10="","",MIN(1,MAX(SMALL($L$8:$L$10,1)*3,IF(_xludf.RANK.EQ(L10,$L$8:$L$10,1)>=2,SMALL($L$8:$L$10,2)*2,0),IF(_xludf.RANK.EQ(L10,$L$8:$L$10,1)>=3,SMALL($L$8:$L$10,3)*1,0))))
A11: LoTT_vs_G20_Std_rq23 | B11: D_rq23 | C11: rq23_exploratory | D11: lott_framework | E11: g20_standard | F11: =COUNTIFS(case_predictions_full500!$B$2:$B$501,"<>",case_predictions_full500!$D$2:$D$501,"<>",case_predictions_full500!$F$2:$F$501,"<>",case_predictions_full500!$C$2:$C$501,"RQ") | G11: =COUNTIFS(case_predictions_full500!$O$2:$O$501,1,case_predictions_full500!$W$2:$W$501,1,case_predictions_full500!$C$2:$C$501,"RQ") | H11: =COUNTIFS(case_predictions_full500!$O$2:$O$501,1,case_predictions_full500!$W$2:$W$501,0,case_predictions_full500!$C$2:$C$501,"RQ") | I11: =COUNTIFS(case_predictions_full500!$O$2:$O$501,0,case_predictions_full500!$W$2:$W$501,1,case_predictions_full500!$C$2:$C$501,"RQ") | J11: =IF(F11=0,"",F11-G11-H11-I11) | K11: =IF(F11=0,"",(H11-I11)/F11) | L11: =IF(H11+I11=0,"",MIN(1,2*_xludf.BINOM.DIST(MIN(H11,I11),H11+I11,0.5,TRUE))) | M11: =IF(L11="","",MIN(1,MAX(SMALL($L$11:$L$13,1)*3,IF(_xludf.RANK.EQ(L11,$L$11:$L$13,1)>=2,SMALL($L$11:$L$13,2)*2,0),IF(_xludf.RANK.EQ(L11,$L$11:$L$13,1)>=3,SMALL($L$11:$L$13,3)*1,0))))
A12: LoTT_vs_G20_CoT_rq23 | B12: D_rq23 | C12: rq23_exploratory | D12: lott_framework | E12: g20_cot | F12: =COUNTIFS(case_predictions_full500!$B$2:$B$501,"<>",case_predictions_full500!$D$2:$D$501,"<>",case_predictions_full500!$G$2:$G$501,"<>",case_predictions_full500!$C$2:$C$501,"RQ") | G12: =COUNTIFS(case_predictions_full500!$O$2:$O$501,1,case_predictions_full500!$AA$2:$AA$501,1,case_predictions_full500!$C$2:$C$501,"RQ") | H12: =COUNTIFS(case_predictions_full500!$O$2:$O$501,1,case_predictions_full500!$AA$2:$AA$501,0,case_predictions_full500!$C$2:$C$501,"RQ") | I12: =COUNTIFS(case_predictions_full500!$O$2:$O$501,0,case_predictions_full500!$AA$2:$AA$501,1,case_predictions_full500!$C$2:$C$501,"RQ") | J12: =IF(F12=0,"",F12-G12-H12-I12) | K12: =IF(F12=0,"",(H12-I12)/F12) | L12: =IF(H12+I12=0,"",MIN(1,2*_xludf.BINOM.DIST(MIN(H12,I12),H12+I12,0.5,TRUE))) | M12: =IF(L12="","",MIN(1,MAX(SMALL($L$11:$L$13,1)*3,IF(_xludf.RANK.EQ(L12,$L$11:$L$13,1)>=2,SMALL($L$11:$L$13,2)*2,0),IF(_xludf.RANK.EQ(L12,$L$11:$L$13,1)>=3,SMALL($L$11:$L$13,3)*1,0))))
A13: LoTT_vs_G20_LS_rq23 | B13: D_rq23 | C13: rq23_exploratory | D13: lott_framework | E13: g20_ls | F13: =COUNTIFS(case_predictions_full500!$B$2:$B$501,"<>",case_predictions_full500!$D$2:$D$501,"<>",case_predictions_full500!$H$2:$H$501,"<>",case_predictions_full500!$C$2:$C$501,"RQ") | G13: =COUNTIFS(case_predictions_full500!$O$2:$O$501,1,case_predictions_full500!$AE$2:$AE$501,1,case_predictions_full500!$C$2:$C$501,"RQ") | H13: =COUNTIFS(case_predictions_full500!$O$2:$O$501,1,case_predictions_full500!$AE$2:$AE$501,0,case_predictions_full500!$C$2:$C$501,"RQ") | I13: =COUNTIFS(case_predictions_full500!$O$2:$O$501,0,case_predictions_full500!$AE$2:$AE$501,1,case_predictions_full500!$C$2:$C$501,"RQ") | J13: =IF(F13=0,"",F13-G13-H13-I13) | K13: =IF(F13=0,"",(H13-I13)/F13) | L13: =IF(H13+I13=0,"",MIN(1,2*_xludf.BINOM.DIST(MIN(H13,I13),H13+I13,0.5,TRUE))) | M13: =IF(L13="","",MIN(1,MAX(SMALL($L$11:$L$13,1)*3,IF(_xludf.RANK.EQ(L13,$L$11:$L$13,1)>=2,SMALL($L$11:$L$13,2)*2,0),IF(_xludf.RANK.EQ(L13,$L$11:$L$13,1)>=3,SMALL($L$11:$L$13,3)*1,0))))
A15: Note | B15: Exact McNemar p-values are formula-ready. Holm-adjusted p-values are computed within each 3-row family block (full500 LoTT, full500 RQ, direct477, rq23).

Sheet mcnemar_positive_recall
A1: comparison_id | B1: family_id | C1: subset | D1: system_A | E1: system_B | F1: n_positive_cases | G1: n11_both_hit_violation | H1: n10_A_hit_B_miss | I1: n01_A_miss_B_hit | J1: n00_both_miss | K1: delta_positive_recall | L1: exact_mcnemar_p_raw | M1: exact_mcnemar_p_holm
A2: LoTT_vs_G20_Std_full500 | B2: A_full500 | C2: full500 | D2: lott_framework | E2: g20_standard | F2: =COUNTIFS(case_predictions_full500!$B$2:$B$501,1,case_predictions_full500!$D$2:$D$501,"<>",case_predictions_full500!$F$2:$F$501,"<>") | G2: =COUNTIFS(case_predictions_full500!$P$2:$P$501,1,case_predictions_full500!$X$2:$X$501,1) | H2: =COUNTIFS(case_predictions_full500!$P$2:$P$501,1,case_predictions_full500!$X$2:$X$501,0) | I2: =COUNTIFS(case_predictions_full500!$P$2:$P$501,0,case_predictions_full500!$X$2:$X$501,1) | J2: =IF(F2=0,"",F2-G2-H2-I2) | K2: =IF(F2=0,"",(H2-I2)/F2) | L2: =IF(H2+I2=0,"",MIN(1,2*_xludf.BINOM.DIST(MIN(H2,I2),H2+I2,0.5,TRUE))) | M2: =IF(L2="","",MIN(1,MAX(SMALL($L$2:$L$4,1)*3,IF(_xludf.RANK.EQ(L2,$L$2:$L$4,1)>=2,SMALL($L$2:$L$4,2)*2,0),IF(_xludf.RANK.EQ(L2,$L$2:$L$4,1)>=3,SMALL($L$2:$L$4,3)*1,0))))
A3: LoTT_vs_G20_CoT_full500 | B3: A_full500 | C3: full500 | D3: lott_framework | E3: g20_cot | F3: =COUNTIFS(case_predictions_full500!$B$2:$B$501,1,case_predictions_full500!$D$2:$D$501,"<>",case_predictions_full500!$G$2:$G$501,"<>") | G3: =COUNTIFS(case_predictions_full500!$P$2:$P$501,1,case_predictions_full500!$AB$2:$AB$501,1) | H3: =COUNTIFS(case_predictions_full500!$P$2:$P$501,1,case_predictions_full500!$AB$2:$AB$501,0) | I3: =COUNTIFS(case_predictions_full500!$P$2:$P$501,0,case_predictions_full500!$AB$2:$AB$501,1) | J3: =IF(F3=0,"",F3-G3-H3-I3) | K3: =IF(F3=0,"",(H3-I3)/F3) | L3: =IF(H3+I3=0,"",MIN(1,2*_xludf.BINOM.DIST(MIN(H3,I3),H3+I3,0.5,TRUE))) | M3: =IF(L3="","",MIN(1,MAX(SMALL($L$2:$L$4,1)*3,IF(_xludf.RANK.EQ(L3,$L$2:$L$4,1)>=2,SMALL($L$2:$L$4,2)*2,0),IF(_xludf.RANK.EQ(L3,$L$2:$L$4,1)>=3,SMALL($L$2:$L$4,3)*1,0))))
A4: LoTT_vs_G20_LS_full500 | B4: A_full500 | C4: full500 | D4: lott_framework | E4: g20_ls | F4: =COUNTIFS(case_predictions_full500!$B$2:$B$501,1,case_predictions_full500!$D$2:$D$501,"<>",case_predictions_full500!$H$2:$H$501,"<>") | G4: =COUNTIFS(case_predictions_full500!$P$2:$P$501,1,case_predictions_full500!$AF$2:$AF$501,1) | H4: =COUNTIFS(case_predictions_full500!$P$2:$P$501,1,case_predictions_full500!$AF$2:$AF$501,0) | I4: =COUNTIFS(case_predictions_full500!$P$2:$P$501,0,case_predictions_full500!$AF$2:$AF$501,1) | J4: =IF(F4=0,"",F4-G4-H4-I4) | K4: =IF(F4=0,"",(H4-I4)/F4) | L4: =IF(H4+I4=0,"",MIN(1,2*_xludf.BINOM.DIST(MIN(H4,I4),H4+I4,0.5,TRUE))) | M4: =IF(L4="","",MIN(1,MAX(SMALL($L$2:$L$4,1)*3,IF(_xludf.RANK.EQ(L4,$L$2:$L$4,1)>=2,SMALL($L$2:$L$4,2)*2,0),IF(_xludf.RANK.EQ(L4,$L$2:$L$4,1)>=3,SMALL($L$2:$L$4,3)*1,0))))
A5: RQ_vs_G20_Std_full500 | B5: B_full500 | C5: full500 | D5: rq_all500 | E5: g20_standard | F5: =COUNTIFS(case_predictions_full500!$B$2:$B$501,1,case_predictions_full500!$E$2:$E$501,"<>",case_predictions_full500!$F$2:$F$501,"<>") | G5: =COUNTIFS(case_predictions_full500!$T$2:$T$501,1,case_predictions_full500!$X$2:$X$501,1) | H5: =COUNTIFS(case_predictions_full500!$T$2:$T$501,1,case_predictions_full500!$X$2:$X$501,0) | I5: =COUNTIFS(case_predictions_full500!$T$2:$T$501,0,case_predictions_full500!$X$2:$X$501,1) | J5: =IF(F5=0,"",F5-G5-H5-I5) | K5: =IF(F5=0,"",(H5-I5)/F5) | L5: =IF(H5+I5=0,"",MIN(1,2*_xludf.BINOM.DIST(MIN(H5,I5),H5+I5,0.5,TRUE))) | M5: =IF(L5="","",MIN(1,MAX(SMALL($L$5:$L$7,1)*3,IF(_xludf.RANK.EQ(L5,$L$5:$L$7,1)>=2,SMALL($L$5:$L$7,2)*2,0),IF(_xludf.RANK.EQ(L5,$L$5:$L$7,1)>=3,SMALL($L$5:$L$7,3)*1,0))))
A6: RQ_vs_G20_CoT_full500 | B6: B_full500 | C6: full500 | D6: rq_all500 | E6: g20_cot | F6: =COUNTIFS(case_predictions_full500!$B$2:$B$501,1,case_predictions_full500!$E$2:$E$501,"<>",case_predictions_full500!$G$2:$G$501,"<>") | G6: =COUNTIFS(case_predictions_full500!$T$2:$T$501,1,case_predictions_full500!$AB$2:$AB$501,1) | H6: =COUNTIFS(case_predictions_full500!$T$2:$T$501,1,case_predictions_full500!$AB$2:$AB$501,0) | I6: =COUNTIFS(case_predictions_full500!$T$2:$T$501,0,case_predictions_full500!$AB$2:$AB$501,1) | J6: =IF(F6=0,"",F6-G6-H6-I6) | K6: =IF(F6=0,"",(H6-I6)/F6) | L6: =IF(H6+I6=0,"",MIN(1,2*_xludf.BINOM.DIST(MIN(H6,I6),H6+I6,0.5,TRUE))) | M6: =IF(L6="","",MIN(1,MAX(SMALL($L$5:$L$7,1)*3,IF(_xludf.RANK.EQ(L6,$L$5:$L$7,1)>=2,SMALL($L$5:$L$7,2)*2,0),IF(_xludf.RANK.EQ(L6,$L$5:$L$7,1)>=3,SMALL($L$5:$L$7,3)*1,0))))
A7: RQ_vs_G20_LS_full500 | B7: B_full500 | C7: full500 | D7: rq_all500 | E7: g20_ls | F7: =COUNTIFS(case_predictions_full500!$B$2:$B$501,1,case_predictions_full500!$E$2:$E$501,"<>",case_predictions_full500!$H$2:$H$501,"<>") | G7: =COUNTIFS(case_predictions_full500!$T$2:$T$501,1,case_predictions_full500!$AF$2:$AF$501,1) | H7: =COUNTIFS(case_predictions_full500!$T$2:$T$501,1,case_predictions_full500!$AF$2:$AF$501,0) | I7: =COUNTIFS(case_predictions_full500!$T$2:$T$501,0,case_predictions_full500!$AF$2:$AF$501,1) | J7: =IF(F7=0,"",F7-G7-H7-I7) | K7: =IF(F7=0,"",(H7-I7)/F7) | L7: =IF(H7+I7=0,"",MIN(1,2*_xludf.BINOM.DIST(MIN(H7,I7),H7+I7,0.5,TRUE))) | M7: =IF(L7="","",MIN(1,MAX(SMALL($L$5:$L$7,1)*3,IF(_xludf.RANK.EQ(L7,$L$5:$L$7,1)>=2,SMALL($L$5:$L$7,2)*2,0),IF(_xludf.RANK.EQ(L7,$L$5:$L$7,1)>=3,SMALL($L$5:$L$7,3)*1,0))))
A8: LoTT_vs_G20_Std_direct477 | B8: C_direct477 | C8: direct477 | D8: lott_framework | E8: g20_standard | F8: =COUNTIFS(case_predictions_full500!$B$2:$B$501,1,case_predictions_full500!$D$2:$D$501,"<>",case_predictions_full500!$F$2:$F$501,"<>",case_predictions_full500!$C$2:$C$501,"Direct") | G8: =COUNTIFS(case_predictions_full500!$P$2:$P$501,1,case_predictions_full500!$X$2:$X$501,1,case_predictions_full500!$C$2:$C$501,"Direct") | H8: =COUNTIFS(case_predictions_full500!$P$2:$P$501,1,case_predictions_full500!$X$2:$X$501,0,case_predictions_full500!$C$2:$C$501,"Direct") | I8: =COUNTIFS(case_predictions_full500!$P$2:$P$501,0,case_predictions_full500!$X$2:$X$501,1,case_predictions_full500!$C$2:$C$501,"Direct") | J8: =IF(F8=0,"",F8-G8-H8-I8) | K8: =IF(F8=0,"",(H8-I8)/F8) | L8: =IF(H8+I8=0,"",MIN(1,2*_xludf.BINOM.DIST(MIN(H8,I8),H8+I8,0.5,TRUE))) | M8: =IF(L8="","",MIN(1,MAX(SMALL($L$8:$L$10,1)*3,IF(_xludf.RANK.EQ(L8,$L$8:$L$10,1)>=2,SMALL($L$8:$L$10,2)*2,0),IF(_xludf.RANK.EQ(L8,$L$8:$L$10,1)>=3,SMALL($L$8:$L$10,3)*1,0))))
A9: LoTT_vs_G20_CoT_direct477 | B9: C_direct477 | C9: direct477 | D9: lott_framework | E9: g20_cot | F9: =COUNTIFS(case_predictions_full500!$B$2:$B$501,1,case_predictions_full500!$D$2:$D$501,"<>",case_predictions_full500!$G$2:$G$501,"<>",case_predictions_full500!$C$2:$C$501,"Direct") | G9: =COUNTIFS(case_predictions_full500!$P$2:$P$501,1,case_predictions_full500!$AB$2:$AB$501,1,case_predictions_full500!$C$2:$C$501,"Direct") | H9: =COUNTIFS(case_predictions_full500!$P$2:$P$501,1,case_predictions_full500!$AB$2:$AB$501,0,case_predictions_full500!$C$2:$C$501,"Direct") | I9: =COUNTIFS(case_predictions_full500!$P$2:$P$501,0,case_predictions_full500!$AB$2:$AB$501,1,case_predictions_full500!$C$2:$C$501,"Direct") | J9: =IF(F9=0,"",F9-G9-H9-I9) | K9: =IF(F9=0,"",(H9-I9)/F9) | L9: =IF(H9+I9=0,"",MIN(1,2*_xludf.BINOM.DIST(MIN(H9,I9),H9+I9,0.5,TRUE))) | M9: =IF(L9="","",MIN(1,MAX(SMALL($L$8:$L$10,1)*3,IF(_xludf.RANK.EQ(L9,$L$8:$L$10,1)>=2,SMALL($L$8:$L$10,2)*2,0),IF(_xludf.RANK.EQ(L9,$L$8:$L$10,1)>=3,SMALL($L$8:$L$10,3)*1,0))))
A10: LoTT_vs_G20_LS_direct477 | B10: C_direct477 | C10: direct477 | D10: lott_framework | E10: g20_ls | F10: =COUNTIFS(case_predictions_full500!$B$2:$B$501,1,case_predictions_full500!$D$2:$D$501,"<>",case_predictions_full500!$H$2:$H$501,"<>",case_predictions_full500!$C$2:$C$501,"Direct") | G10: =COUNTIFS(case_predictions_full500!$P$2:$P$501,1,case_predictions_full500!$AF$2:$AF$501,1,case_predictions_full500!$C$2:$C$501,"Direct") | H10: =COUNTIFS(case_predictions_full500!$P$2:$P$501,1,case_predictions_full500!$AF$2:$AF$501,0,case_predictions_full500!$C$2:$C$501,"Direct") | I10: =COUNTIFS(case_predictions_full500!$P$2:$P$501,0,case_predictions_full500!$AF$2:$AF$501,1,case_predictions_full500!$C$2:$C$501,"Direct") | J10: =IF(F10=0,"",F10-G10-H10-I10) | K10: =IF(F10=0,"",(H10-I10)/F10) | L10: =IF(H10+I10=0,"",MIN(1,2*_xludf.BINOM.DIST(MIN(H10,I10),H10+I10,0.5,TRUE))) | M10: =IF(L10="","",MIN(1,MAX(SMALL($L$8:$L$10,1)*3,IF(_xludf.RANK.EQ(L10,$L$8:$L$10,1)>=2,SMALL($L$8:$L$10,2)*2,0),IF(_xludf.RANK.EQ(L10,$L$8:$L$10,1)>=3,SMALL($L$8:$L$10,3)*1,0))))
A11: LoTT_vs_G20_Std_rq23 | B11: D_rq23 | C11: rq23_exploratory | D11: lott_framework | E11: g20_standard | F11: =COUNTIFS(case_predictions_full500!$B$2:$B$501,1,case_predictions_full500!$D$2:$D$501,"<>",case_predictions_full500!$F$2:$F$501,"<>",case_predictions_full500!$C$2:$C$501,"RQ") | G11: =COUNTIFS(case_predictions_full500!$P$2:$P$501,1,case_predictions_full500!$X$2:$X$501,1,case_predictions_full500!$C$2:$C$501,"RQ") | H11: =COUNTIFS(case_predictions_full500!$P$2:$P$501,1,case_predictions_full500!$X$2:$X$501,0,case_predictions_full500!$C$2:$C$501,"RQ") | I11: =COUNTIFS(case_predictions_full500!$P$2:$P$501,0,case_predictions_full500!$X$2:$X$501,1,case_predictions_full500!$C$2:$C$501,"RQ") | J11: =IF(F11=0,"",F11-G11-H11-I11) | K11: =IF(F11=0,"",(H11-I11)/F11) | L11: =IF(H11+I11=0,"",MIN(1,2*_xludf.BINOM.DIST(MIN(H11,I11),H11+I11,0.5,TRUE))) | M11: =IF(L11="","",MIN(1,MAX(SMALL($L$11:$L$13,1)*3,IF(_xludf.RANK.EQ(L11,$L$11:$L$13,1)>=2,SMALL($L$11:$L$13,2)*2,0),IF(_xludf.RANK.EQ(L11,$L$11:$L$13,1)>=3,SMALL($L$11:$L$13,3)*1,0))))
A12: LoTT_vs_G20_CoT_rq23 | B12: D_rq23 | C12: rq23_exploratory | D12: lott_framework | E12: g20_cot | F12: =COUNTIFS(case_predictions_full500!$B$2:$B$501,1,case_predictions_full500!$D$2:$D$501,"<>",case_predictions_full500!$G$2:$G$501,"<>",case_predictions_full500!$C$2:$C$501,"RQ") | G12: =COUNTIFS(case_predictions_full500!$P$2:$P$501,1,case_predictions_full500!$AB$2:$AB$501,1,case_predictions_full500!$C$2:$C$501,"RQ") | H12: =COUNTIFS(case_predictions_full500!$P$2:$P$501,1,case_predictions_full500!$AB$2:$AB$501,0,case_predictions_full500!$C$2:$C$501,"RQ") | I12: =COUNTIFS(case_predictions_full500!$P$2:$P$501,0,case_predictions_full500!$AB$2:$AB$501,1,case_predictions_full500!$C$2:$C$501,"RQ") | J12: =IF(F12=0,"",F12-G12-H12-I12) | K12: =IF(F12=0,"",(H12-I12)/F12) | L12: =IF(H12+I12=0,"",MIN(1,2*_xludf.BINOM.DIST(MIN(H12,I12),H12+I12,0.5,TRUE))) | M12: =IF(L12="","",MIN(1,MAX(SMALL($L$11:$L$13,1)*3,IF(_xludf.RANK.EQ(L12,$L$11:$L$13,1)>=2,SMALL($L$11:$L$13,2)*2,0),IF(_xludf.RANK.EQ(L12,$L$11:$L$13,1)>=3,SMALL($L$11:$L$13,3)*1,0))))
A13: LoTT_vs_G20_LS_rq23 | B13: D_rq23 | C13: rq23_exploratory | D13: lott_framework | E13: g20_ls | F13: =COUNTIFS(case_predictions_full500!$B$2:$B$501,1,case_predictions_full500!$D$2:$D$501,"<>",case_predictions_full500!$H$2:$H$501,"<>",case_predictions_full500!$C$2:$C$501,"RQ") | G13: =COUNTIFS(case_predictions_full500!$P$2:$P$501,1,case_predictions_full500!$AF$2:$AF$501,1,case_predictions_full500!$C$2:$C$501,"RQ") | H13: =COUNTIFS(case_predictions_full500!$P$2:$P$501,1,case_predictions_full500!$AF$2:$AF$501,0,case_predictions_full500!$C$2:$C$501,"RQ") | I13: =COUNTIFS(case_predictions_full500!$P$2:$P$501,0,case_predictions_full500!$AF$2:$AF$501,1,case_predictions_full500!$C$2:$C$501,"RQ") | J13: =IF(F13=0,"",F13-G13-H13-I13) | K13: =IF(F13=0,"",(H13-I13)/F13) | L13: =IF(H13+I13=0,"",MIN(1,2*_xludf.BINOM.DIST(MIN(H13,I13),H13+I13,0.5,TRUE))) | M13: =IF(L13="","",MIN(1,MAX(SMALL($L$11:$L$13,1)*3,IF(_xludf.RANK.EQ(L13,$L$11:$L$13,1)>=2,SMALL($L$11:$L$13,2)*2,0),IF(_xludf.RANK.EQ(L13,$L$11:$L$13,1)>=3,SMALL($L$11:$L$13,3)*1,0))))
A15: Note | B15: Exact McNemar p-values are formula-ready. Holm-adjusted p-values are computed within each 3-row family block (full500 LoTT, full500 RQ, direct477, rq23).

Sheet mcnemar_negative_recall
A1: comparison_id | B1: family_id | C1: subset | D1: system_A | E1: system_B | F1: n_negative_cases | G1: n11_both_correct_nonviolation | H1: n10_A_correct_B_falsepositive | I1: n01_A_falsepositive_B_correct | J1: n00_both_falsepositive | K1: delta_negative_recall | L1: exact_mcnemar_p_raw | M1: exact_mcnemar_p_holm
A2: LoTT_vs_G20_Std_full500 | B2: A_full500 | C2: full500 | D2: lott_framework | E2: g20_standard | F2: =COUNTIFS(case_predictions_full500!$B$2:$B$501,0,case_predictions_full500!$D$2:$D$501,"<>",case_predictions_full500!$F$2:$F$501,"<>") | G2: =COUNTIFS(case_predictions_full500!$Q$2:$Q$501,1,case_predictions_full500!$Y$2:$Y$501,1) | H2: =COUNTIFS(case_predictions_full500!$Q$2:$Q$501,1,case_predictions_full500!$Y$2:$Y$501,0) | I2: =COUNTIFS(case_predictions_full500!$Q$2:$Q$501,0,case_predictions_full500!$Y$2:$Y$501,1) | J2: =IF(F2=0,"",F2-G2-H2-I2) | K2: =IF(F2=0,"",(H2-I2)/F2) | L2: =IF(H2+I2=0,"",MIN(1,2*_xludf.BINOM.DIST(MIN(H2,I2),H2+I2,0.5,TRUE))) | M2: =IF(L2="","",MIN(1,MAX(SMALL($L$2:$L$4,1)*3,IF(_xludf.RANK.EQ(L2,$L$2:$L$4,1)>=2,SMALL($L$2:$L$4,2)*2,0),IF(_xludf.RANK.EQ(L2,$L$2:$L$4,1)>=3,SMALL($L$2:$L$4,3)*1,0))))
A3: LoTT_vs_G20_CoT_full500 | B3: A_full500 | C3: full500 | D3: lott_framework | E3: g20_cot | F3: =COUNTIFS(case_predictions_full500!$B$2:$B$501,0,case_predictions_full500!$D$2:$D$501,"<>",case_predictions_full500!$G$2:$G$501,"<>") | G3: =COUNTIFS(case_predictions_full500!$Q$2:$Q$501,1,case_predictions_full500!$AC$2:$AC$501,1) | H3: =COUNTIFS(case_predictions_full500!$Q$2:$Q$501,1,case_predictions_full500!$AC$2:$AC$501,0) | I3: =COUNTIFS(case_predictions_full500!$Q$2:$Q$501,0,case_predictions_full500!$AC$2:$AC$501,1) | J3: =IF(F3=0,"",F3-G3-H3-I3) | K3: =IF(F3=0,"",(H3-I3)/F3) | L3: =IF(H3+I3=0,"",MIN(1,2*_xludf.BINOM.DIST(MIN(H3,I3),H3+I3,0.5,TRUE))) | M3: =IF(L3="","",MIN(1,MAX(SMALL($L$2:$L$4,1)*3,IF(_xludf.RANK.EQ(L3,$L$2:$L$4,1)>=2,SMALL($L$2:$L$4,2)*2,0),IF(_xludf.RANK.EQ(L3,$L$2:$L$4,1)>=3,SMALL($L$2:$L$4,3)*1,0))))
A4: LoTT_vs_G20_LS_full500 | B4: A_full500 | C4: full500 | D4: lott_framework | E4: g20_ls | F4: =COUNTIFS(case_predictions_full500!$B$2:$B$501,0,case_predictions_full500!$D$2:$D$501,"<>",case_predictions_full500!$H$2:$H$501,"<>") | G4: =COUNTIFS(case_predictions_full500!$Q$2:$Q$501,1,case_predictions_full500!$AG$2:$AG$501,1) | H4: =COUNTIFS(case_predictions_full500!$Q$2:$Q$501,1,case_predictions_full500!$AG$2:$AG$501,0) | I4: =COUNTIFS(case_predictions_full500!$Q$2:$Q$501,0,case_predictions_full500!$AG$2:$AG$501,1) | J4: =IF(F4=0,"",F4-G4-H4-I4) | K4: =IF(F4=0,"",(H4-I4)/F4) | L4: =IF(H4+I4=0,"",MIN(1,2*_xludf.BINOM.DIST(MIN(H4,I4),H4+I4,0.5,TRUE))) | M4: =IF(L4="","",MIN(1,MAX(SMALL($L$2:$L$4,1)*3,IF(_xludf.RANK.EQ(L4,$L$2:$L$4,1)>=2,SMALL($L$2:$L$4,2)*2,0),IF(_xludf.RANK.EQ(L4,$L$2:$L$4,1)>=3,SMALL($L$2:$L$4,3)*1,0))))
A5: RQ_vs_G20_Std_full500 | B5: B_full500 | C5: full500 | D5: rq_all500 | E5: g20_standard | F5: =COUNTIFS(case_predictions_full500!$B$2:$B$501,0,case_predictions_full500!$E$2:$E$501,"<>",case_predictions_full500!$F$2:$F$501,"<>") | G5: =COUNTIFS(case_predictions_full500!$U$2:$U$501,1,case_predictions_full500!$Y$2:$Y$501,1) | H5: =COUNTIFS(case_predictions_full500!$U$2:$U$501,1,case_predictions_full500!$Y$2:$Y$501,0) | I5: =COUNTIFS(case_predictions_full500!$U$2:$U$501,0,case_predictions_full500!$Y$2:$Y$501,1) | J5: =IF(F5=0,"",F5-G5-H5-I5) | K5: =IF(F5=0,"",(H5-I5)/F5) | L5: =IF(H5+I5=0,"",MIN(1,2*_xludf.BINOM.DIST(MIN(H5,I5),H5+I5,0.5,TRUE))) | M5: =IF(L5="","",MIN(1,MAX(SMALL($L$5:$L$7,1)*3,IF(_xludf.RANK.EQ(L5,$L$5:$L$7,1)>=2,SMALL($L$5:$L$7,2)*2,0),IF(_xludf.RANK.EQ(L5,$L$5:$L$7,1)>=3,SMALL($L$5:$L$7,3)*1,0))))
A6: RQ_vs_G20_CoT_full500 | B6: B_full500 | C6: full500 | D6: rq_all500 | E6: g20_cot | F6: =COUNTIFS(case_predictions_full500!$B$2:$B$501,0,case_predictions_full500!$E$2:$E$501,"<>",case_predictions_full500!$G$2:$G$501,"<>") | G6: =COUNTIFS(case_predictions_full500!$U$2:$U$501,1,case_predictions_full500!$AC$2:$AC$501,1) | H6: =COUNTIFS(case_predictions_full500!$U$2:$U$501,1,case_predictions_full500!$AC$2:$AC$501,0) | I6: =COUNTIFS(case_predictions_full500!$U$2:$U$501,0,case_predictions_full500!$AC$2:$AC$501,1) | J6: =IF(F6=0,"",F6-G6-H6-I6) | K6: =IF(F6=0,"",(H6-I6)/F6) | L6: =IF(H6+I6=0,"",MIN(1,2*_xludf.BINOM.DIST(MIN(H6,I6),H6+I6,0.5,TRUE))) | M6: =IF(L6="","",MIN(1,MAX(SMALL($L$5:$L$7,1)*3,IF(_xludf.RANK.EQ(L6,$L$5:$L$7,1)>=2,SMALL($L$5:$L$7,2)*2,0),IF(_xludf.RANK.EQ(L6,$L$5:$L$7,1)>=3,SMALL($L$5:$L$7,3)*1,0))))
A7: RQ_vs_G20_LS_full500 | B7: B_full500 | C7: full500 | D7: rq_all500 | E7: g20_ls | F7: =COUNTIFS(case_predictions_full500!$B$2:$B$501,0,case_predictions_full500!$E$2:$E$501,"<>",case_predictions_full500!$H$2:$H$501,"<>") | G7: =COUNTIFS(case_predictions_full500!$U$2:$U$501,1,case_predictions_full500!$AG$2:$AG$501,1) | H7: =COUNTIFS(case_predictions_full500!$U$2:$U$501,1,case_predictions_full500!$AG$2:$AG$501,0) | I7: =COUNTIFS(case_predictions_full500!$U$2:$U$501,0,case_predictions_full500!$AG$2:$AG$501,1) | J7: =IF(F7=0,"",F7-G7-H7-I7) | K7: =IF(F7=0,"",(H7-I7)/F7) | L7: =IF(H7+I7=0,"",MIN(1,2*_xludf.BINOM.DIST(MIN(H7,I7),H7+I7,0.5,TRUE))) | M7: =IF(L7="","",MIN(1,MAX(SMALL($L$5:$L$7,1)*3,IF(_xludf.RANK.EQ(L7,$L$5:$L$7,1)>=2,SMALL($L$5:$L$7,2)*2,0),IF(_xludf.RANK.EQ(L7,$L$5:$L$7,1)>=3,SMALL($L$5:$L$7,3)*1,0))))
A8: LoTT_vs_G20_Std_direct477 | B8: C_direct477 | C8: direct477 | D8: lott_framework | E8: g20_standard | F8: =COUNTIFS(case_predictions_full500!$B$2:$B$501,0,case_predictions_full500!$D$2:$D$501,"<>",case_predictions_full500!$F$2:$F$501,"<>",case_predictions_full500!$C$2:$C$501,"Direct") | G8: =COUNTIFS(case_predictions_full500!$Q$2:$Q$501,1,case_predictions_full500!$Y$2:$Y$501,1,case_predictions_full500!$C$2:$C$501,"Direct") | H8: =COUNTIFS(case_predictions_full500!$Q$2:$Q$501,1,case_predictions_full500!$Y$2:$Y$501,0,case_predictions_full500!$C$2:$C$501,"Direct") | I8: =COUNTIFS(case_predictions_full500!$Q$2:$Q$501,0,case_predictions_full500!$Y$2:$Y$501,1,case_predictions_full500!$C$2:$C$501,"Direct") | J8: =IF(F8=0,"",F8-G8-H8-I8) | K8: =IF(F8=0,"",(H8-I8)/F8) | L8: =IF(H8+I8=0,"",MIN(1,2*_xludf.BINOM.DIST(MIN(H8,I8),H8+I8,0.5,TRUE))) | M8: =IF(L8="","",MIN(1,MAX(SMALL($L$8:$L$10,1)*3,IF(_xludf.RANK.EQ(L8,$L$8:$L$10,1)>=2,SMALL($L$8:$L$10,2)*2,0),IF(_xludf.RANK.EQ(L8,$L$8:$L$10,1)>=3,SMALL($L$8:$L$10,3)*1,0))))
